Workbook

Sheet Elemek
A1: Elem | B1: Vegyjel | C1: Rendszám | D1: Atomtömeg | E1: Sűrűség | F1: Olvadáspont | G1: Forráspont | H1: Izotópok száma | I1: Felfedezés éve | J1: Felfedező
A2: Aktínium | B2: Ac | C2: 89 | D2: 227 | E2: 10 | F2: 1050 | G2: 3198 | H2: 11 | I2: 1899 | J2: Debierne
A3: Alumínium | B3: Al | C3: 13 | D3: 26.982 | E3: 2.7 | F3: 660.47 | G3: 2519 | H3: 8 | I3: 1827 | J3: Wöhler
A4: Amerícium | B4: Am | C4: 95 | D4: 243 | E4: 12 | F4: 1176 | G4: 2607 | H4: 133 | I4: 1944 | J4: Seaborg et al.
A5: Antimon | B5: Sb | C5: 51 | D5: 121.76 | E5: 6.697 | F5: 630.78 | G5: 1587 | H5: 29 | I5: - | J5: Early historic times
A6: Arany | B6: Au | C6: 79 | D6: 196.97 | E6: 19.3 | F6: 1064.33 | G6: 2856 | H6: 21 | I6: - | J6: -
A7: Argon | B7: Ar | C7: 18 | D7: 39.95 | E7: 0.001784 | F7: -189.2 | G7: -185.7 | H7: 8 | I7: 1894 | J7: Rayleigh and Ramsay
A8: Arzén | B8: As | C8: 33 | D8: 74.922 | E8: 5.727 | F8: 817 | G8: 614 | H8: 14 | I8: 1250? | J8: Albertus Magnus
A9: Asztácium | B9: At | C9: 85 | D9: 210 | E9: 8.93 | F9: 302 | G9: 337 | H9: 21 | I9: 1940 | J9: Corson et al.
A10: Bárium | B10: Ba | C10: 56 | D10: 137.33 | E10: 3.51 | F10: 727 | G10: 1897 | H10: 25 | I10: 1808 | J10: Davy
A11: Berillium | B11: Be | C11: 4 | D11: 9.0122 | E11: 1.85 | F11: 1287 | G11: 2469 | H11: 6 | I11: 1798 | J11: Vauquelin
A12: Berkélium | B12: Bk | C12: 97 | D12: 247 | E12: 14.78 | F12: 986 | G12: 2627 | H12: 83 | I12: 1949 | J12: Seaborg et al.
A13: Bizmut | B13: Bi | C13: 83 | D13: 208.98 | E13: 9.78 | F13: 271.7 | G13: 1564 | H13: 19 | I13: 1753 | J13: Geoffroy
A14: Bór | B14: B | C14: 5 | D14: 10.81 | E14: 2.34 | F14: 2076 | G14: 3927 | H14: 6 | I14: 1808 | J14: Gay-Lussac and
I15: Thénard; Davy
A16: Bórium | B16: Bh | C16: 107 | D16: 270 | E16: 26.5 | F16: - | G16: - | H16: - | I16: 1981 | J16: Armbruster and Münzenberg
A17: Bróm | B17: Br | C17: 35 | D17: 79.904 | E17: 3.1028 | F17: -7.2 | G17: 59 | H17: 19 | I17: 1826 | J17: Balard
A18: Cérium | B18: Ce | C18: 58 | D18: 140.12 | E18: 6.77 | F18: 795 | G18: 3443 | H18: 19 | I18: 1803 | J18: Berzelius and
I19: Hisinger; Klaproth
A20: Cézium | B20: Cs | C20: 55 | D20: 132.91 | E20: 1.93 | F20: 28.59 | G20: 671 | H20: 22 | I20: 1860 | J20: Bunsen and Kirchoff
A21: Cink | B21: Zn | C21: 30 | D21: 65.38 | E21: 7.14 | F21: 419.88 | G21: 907 | H21: 15 | I21: - | J21: -
A22: Cirkónium | B22: Zr | C22: 40 | D22: 91.224 | E22: 6.52 | F22: 1855 | G22: 4409 | H22: 20 | I22: 1789 | J22: Klaproth
A23: Diszprózium | B23: Dy | C23: 66 | D23: 162.5 | E23: 8.54 | F23: 1407 | G23: 2567 | H23: 21 | I23: 1886 | J23: Boisbaudran
A24: Dubnium | B24: Db | C24: 105 | D24: 268 | E24: -21.6 | F24: - | G24: - | H24: - | I24: 1970 | J24: Ghiorso et al,
A25: Einsteinium | B25: Es | C25: 99 | D25: 252 | E25: 8.84 | F25: 860 | G25: -1542 | H25: 123 | I25: 1952 | J25: Ghiorso et al,
A26: Erbium | B26: Er | C26: 68 | D26: 167.26 | E26: 9.066 | F26: 1529 | G26: 2868 | H26: 16 | I26: 1843 | J26: Mosander
A27: Európium | B27: Eu | C27: 63 | D27: 151.96 | E27: 5.244 | F27: 826 | G27: 1529 | H27: 21 | I27: 1896 | J27: Demarcay
A28: Ezüst | B28: Ag | C28: 47 | D28: 107.87 | E28: 10.49 | F28: 961.93 | G28: 2162 | H28: 27 | I28: - | J28: -
A29: Fermium | B29: Fm | C29: 100 | D29: 257 | E29: 9.7 | F29: 852 | G29: - | H29: 103 | I29: 1953 | J29: Ghiorso et al,
A30: Fluor | B30: F | C30: 9 | D30: 18.998 | E30: 0.001696 | F30: -219.47 | G30: -187.97 | H30: 6 | I30: 1886 | J30: Moissan
A31: Foszfor | B31: P | C31: 15 | D31: 30.974 | E31: 1.823 | F31: 44.3 | G31: 277 | H31: 7 | I31: 1669 | J31: Brand
A32: Francium | B32: Fr | C32: 87 | D32: 223 | E32: -2.48 | F32: 8 | G32: 617 | H32: 21 | I32: 1938 | J32: Perey
A33: Gadolínium | B33: Gd | C33: 64 | D33: 157.25 | E33: 7.9 | F33: 1312 | G33: 3273 | H33: 17 | I33: 1880 | J33: Marignac
A34: Gallium | B34: Ga | C34: 31 | D34: 69.723 | E34: 5.91 | F34: 29.9146 | G34: 2400 | H34: 14 | I34: 1875 | J34: Boisbaudran
A35: Germánium | B35: Ge | C35: 32 | D35: 72.63 | E35: 5.323 | F35: 938.4 | G35: 2833 | H35: 17 | I35: 1886 | J35: Winkler
A36: Hafnium | B36: Hf | C36: 72 | D36: 178.49 | E36: 13.31 | F36: 2233 | G36: 4603 | H36: 17 | I36: 1923 | J36: Coster and von Hevesy
A37: Hassium | B37: Hs | C37: 108 | D37: 269 | E37: 28 | F37: - | G37: - | H37: - | I37: 1983 | J37: Armbruster and Münzenberg
A38: Hélium | B38: He | C38: 2 | D38: 4.0026 | E38: 0.0001785 | F38: -272.2 | G38: -268.78 | H38: 5 | I38: 1868 | J38: Janssen
A39: Hidrogén | B39: H | C39: 1 | D39: 1.008 | E39: 8.988e-05 | F39: -258.99 | G39: -252.72 | H39: 3 | I39: 1766 | J39: Cavendish
A40: Higany | B40: Hg | C40: 80 | D40: 200.59 | E40: 13.534 | F40: -38.57 | G40: 356.88 | H40: 26 | I40: - | J40: -
...

Sheet Vas
A1: Elem
A2: Vas
A4: =Elemek!B$1 -> Vegyjel | B4: =DGET(Elemek!$A$1:$K$113,Vas!A4,Vas!$A$1:$A$2) -> Fe
A5: =Elemek!C$1 -> Rendszám | B5: =DGET(Elemek!$A$1:$K$113,Vas!A5,Vas!$A$1:$A$2) -> 26
A6: =Elemek!D$1 -> Atomtömeg | B6: =DGET(Elemek!$A$1:$K$113,Vas!A6,Vas!$A$1:$A$2) -> 55.845
A7: =Elemek!E$1 -> Sűrűség | B7: =DGET(Elemek!$A$1:$K$113,Vas!A7,Vas!$A$1:$A$2) -> 7.874
A8: =Elemek!F$1 -> Olvadáspont | B8: =DGET(Elemek!$A$1:$K$113,Vas!A8,Vas!$A$1:$A$2) -> 1538
A9: =Elemek!G$1 -> Forráspont | B9: =DGET(Elemek!$A$1:$K$113,Vas!A9,Vas!$A$1:$A$2) -> 2861
A10: Halmazállapot | B10: =IF(B8>35,"szilárd",IF(B9<15,"légnemű",IF(AND(B8<15,B9>35),"folyékon","hőmérsékletfüggő"))) -> szilárd

Sheet Izotópok
A1: ssz | B1: Elem | C1: A | D1: Z | E1: N | F1: E | H1: Fe | L1: ssz | M1: Z | N1: N | O1: E | P1: A | Q1: Elem | R1: E1 | S1: E2 | T1: E3
A2: 1 | B2: Fe | C2: 56 | D2: 26 | E2: 30 | F2: 9.153567 | H2: =IF(B2=$H$1,COUNT($H$2:H3)+1," ") -> 0 | L2: 1 | M2: 26 | N2: 30 | O2: 9.153567 | P2: =N2+M2 -> 56 | Q2: =INDEX(Elemek!$B$2:$B$113,MATCH(M2,Elemek!$C$2:$C$113,0)) -> Fe | R2: =IF(NOT(ISBLANK(O2)),O2,ROUNDDOWN(AVERAGE($O$2:$O$990),2)) -> 9.153567 | S2: =IF(ISBLANK(O2),ROUNDDOWN(AVERAGEIF($M$2:$M$990,M2,$O$2:$O$990),2),O2) -> 9.153567
A3: 2 | B3: Ni | C3: 62 | D3: 28 | E3: 34 | F3: 9.147877 | H3: =IF(B3=$H$1,COUNT($H$2:H4)+1," ") | L3: 2 | M3: 28 | N3: 34 | O3: 9.147877 | P3: =N3+M3 -> 62 | Q3: =INDEX(Elemek!$B$2:$B$113,MATCH(M3,Elemek!$C$2:$C$113,0)) -> Ni | R3: =IF(NOT(ISBLANK(O3)),O3,ROUNDDOWN(AVERAGE($O$2:$O$990),2)) -> 9.147877 | S3: =IF(ISBLANK(O3),ROUNDDOWN(AVERAGEIF($M$2:$M$990,M3,$O$2:$O$990),2),O3) -> 9.147877
A4: 3 | B4: Ni | C4: 60 | D4: 28 | E4: 32 | F4: 9.145862 | H4: =IF(B4=$H$1,COUNT($H$2:H5)+1," ") | L4: 3 | M4: 28 | N4: 32 | O4: 9.145862 | P4: =N4+M4 -> 60 | Q4: =INDEX(Elemek!$B$2:$B$113,MATCH(M4,Elemek!$C$2:$C$113,0)) -> Ni | R4: =IF(NOT(ISBLANK(O4)),O4,ROUNDDOWN(AVERAGE($O$2:$O$990),2)) -> 9.145862 | S4: =IF(ISBLANK(O4),ROUNDDOWN(AVERAGEIF($M$2:$M$990,M4,$O$2:$O$990),2),O4) -> 9.145862
A5: 4 | B5: Fe | C5: 58 | D5: 26 | E5: 32 | F5: 9.142938 | H5: =IF(B5=$H$1,COUNT($H$2:H6)+1," ") -> 0 | L5: 4 | M5: 26 | N5: 32 | O5: 9.142938 | P5: =N5+M5 -> 58 | Q5: =INDEX(Elemek!$B$2:$B$113,MATCH(M5,Elemek!$C$2:$C$113,0)) -> Fe | R5: =IF(NOT(ISBLANK(O5)),O5,ROUNDDOWN(AVERAGE($O$2:$O$990),2)) -> 9.142938 | S5: =IF(ISBLANK(O5),ROUNDDOWN(AVERAGEIF($M$2:$M$990,M5,$O$2:$O$990),2),O5) -> 9.142938
A6: 5 | B6: Cr | C6: 52 | D6: 24 | E6: 28 | F6: 9.137037 | H6: =IF(B6=$H$1,COUNT($H$2:H7)+1," ") | L6: 5 | M6: 24 | N6: 28 | O6: 9.137037 | P6: =N6+M6 -> 52 | Q6: =INDEX(Elemek!$B$2:$B$113,MATCH(M6,Elemek!$C$2:$C$113,0)) -> Cr | R6: =IF(NOT(ISBLANK(O6)),O6,ROUNDDOWN(AVERAGE($O$2:$O$990),2)) -> 9.137037 | S6: =IF(ISBLANK(O6),ROUNDDOWN(AVERAGEIF($M$2:$M$990,M6,$O$2:$O$990),2),O6) -> 9.137037
A7: 6 | B7: Fe | C7: 57 | D7: 26 | E7: 31 | F7: 9.127119 | H7: =IF(B7=$H$1,COUNT($H$2:H8)+1," ") -> 0 | L7: 6 | M7: 26 | N7: 31 | O7: 9.127119 | P7: =N7+M7 -> 57 | Q7: =INDEX(Elemek!$B$2:$B$113,MATCH(M7,Elemek!$C$2:$C$113,0)) -> Fe | R7: =IF(NOT(ISBLANK(O7)),O7,ROUNDDOWN(AVERAGE($O$2:$O$990),2)) -> 9.127119 | S7: =IF(ISBLANK(O7),ROUNDDOWN(AVERAGEIF($M$2:$M$990,M7,$O$2:$O$990),2),O7) -> 9.127119
A8: 7 | B8: Co | C8: 59 | D8: 27 | E8: 32 | F8: 9.126046 | H8: =IF(B8=$H$1,COUNT($H$2:H9)+1," ") | L8: 7 | M8: 27 | N8: 32 | O8: 9.126046 | P8: =N8+M8 -> 59 | Q8: =INDEX(Elemek!$B$2:$B$113,MATCH(M8,Elemek!$C$2:$C$113,0)) -> Co | R8: =IF(NOT(ISBLANK(O8)),O8,ROUNDDOWN(AVERAGE($O$2:$O$990),2)) -> 9.126046 | S8: =IF(ISBLANK(O8),ROUNDDOWN(AVERAGEIF($M$2:$M$990,M8,$O$2:$O$990),2),O8) -> 9.126046
A9: 8 | B9: Cr | C9: 54 | D9: 24 | E9: 30 | F9: 9.125633 | H9: =IF(B9=$H$1,COUNT($H$2:H10)+1," ") | L9: 8 | M9: 24 | N9: 30 | O9: 9.125633 | P9: =N9+M9 -> 54 | Q9: =INDEX(Elemek!$B$2:$B$113,MATCH(M9,Elemek!$C$2:$C$113,0)) -> Cr | R9: =IF(NOT(ISBLANK(O9)),O9,ROUNDDOWN(AVERAGE($O$2:$O$990),2)) -> 9.125633 | S9: =IF(ISBLANK(O9),ROUNDDOWN(AVERAGEIF($M$2:$M$990,M9,$O$2:$O$990),2),O9) -> 9.125633
A10: 9 | B10: Ni | C10: 61 | D10: 28 | E10: 33 | F10: 9.124129 | H10: =IF(B10=$H$1,COUNT($H$2:H11)+1," ") | L10: 9 | M10: 28 | N10: 33 | O10: 9.124129 | P10: =N10+M10 -> 61 | Q10: =INDEX(Elemek!$B$2:$B$113,MATCH(M10,Elemek!$C$2:$C$113,0)) -> Ni | R10: =IF(NOT(ISBLANK(O10)),O10,ROUNDDOWN(AVERAGE($O$2:$O$990),2)) -> 9.124129 | S10: =IF(ISBLANK(O10),ROUNDDOWN(AVERAGEIF($M$2:$M$990,M10,$O$2:$O$990),2),O10) -> 9.124129
A11: 10 | B11: Mn | C11: 55 | D11: 25 | E11: 30 | F11: 9.120611 | H11: =IF(B11=$H$1,COUNT($H$2:H12)+1," ") | L11: 10 | M11: 25 | N11: 30 | O11: 9.120611 | P11: =N11+M11 -> 55 | Q11: =INDEX(Elemek!$B$2:$B$113,MATCH(M11,Elemek!$C$2:$C$113,0)) -> Mn | R11: =IF(NOT(ISBLANK(O11)),O11,ROUNDDOWN(AVERAGE($O$2:$O$990),2)) -> 9.120611 | S11: =IF(ISBLANK(O11),ROUNDDOWN(AVERAGEIF($M$2:$M$990,M11,$O$2:$O$990),2),O11) -> 9.120611
A12: 11 | B12: Ni | C12: 64 | D12: 28 | E12: 36 | F12: 9.119754 | H12: =IF(B12=$H$1,COUNT($H$2:H13)+1," ") | L12: 11 | M12: 28 | N12: 36 | O12: 9.119754 | P12: =N12+M12 -> 64 | Q12: =INDEX(Elemek!$B$2:$B$113,MATCH(M12,Elemek!$C$2:$C$113,0)) -> Ni | R12: =IF(NOT(ISBLANK(O12)),O12,ROUNDDOWN(AVERAGE($O$2:$O$990),2)) -> 9.119754 | S12: =IF(ISBLANK(O12),ROUNDDOWN(AVERAGEIF($M$2:$M$990,M12,$O$2:$O$990),2),O12) -> 9.119754
A13: 394 | B13: Fe | C13: 55 | D13: 26 | E13: 29 | F13: 9.116407 | H13: =IF(B13=$H$1,COUNT($H$2:H14)+1," ") -> 0 | L13: 12 | M13: 30 | N13: 36 | O13: 9.115258 | P13: =N13+M13 -> 66 | Q13: =INDEX(Elemek!$B$2:$B$113,MATCH(M13,Elemek!$C$2:$C$113,0)) -> Zn | R13: =IF(NOT(ISBLANK(O13)),O13,ROUNDDOWN(AVERAGE($O$2:$O$990),2)) -> 9.115258 | S13: =IF(ISBLANK(O13),ROUNDDOWN(AVERAGEIF($M$2:$M$990,M13,$O$2:$O$990),2),O13) -> 9.115258
... A365: 106 | B365: Ba | C365: 134 | D365: 56 | E365: 78 | F365: 8.735133 | H365: =IF(B365=$H$1,COUNT($H$2:H366)+1," ") | L365: 364 | M365: 83 | N365: 124 | O365: 8.168209 | P365: =N365+M365 -> 207 | Q365: =INDEX(Elemek!$B$2:$B$113,MATCH(M365,Elemek!$C$2:$C$113,0)) -> Bi | R365: =IF(NOT(ISBLANK(O365)),O365,ROUNDDOWN(AVERAGE($O$2:$O$990),2)) -> 8.168209 | S365: =IF(ISBLANK(O365),ROUNDDOWN(AVERAGEIF($M$2:$M$990,M365,$O$2:$O$990),2),O365) -> 8.168209
A366: 107 | B366: Cs | C366: 133 | D366: 55 | E366: 78 | F366: 8.733515 | H366: =IF(B366=$H$1,COUNT($H$2:H367)+1," ") | L366: 365 | M366: 72 | N366: 106 | P366: =N366+M366 -> 178 | Q366: =INDEX(Elemek!$B$2:$B$113,MATCH(M366,Elemek!$C$2:$C$113,0)) -> Hf | R366: =IF(NOT(ISBLANK(O366)),O366,ROUNDDOWN(AVERAGE($O$2:$O$990),2)) -> #DIV/0! | S366: =IF(ISBLANK(O366),ROUNDDOWN(AVERAGEIF($M$2:$M$990,M366,$O$2:$O$990),2),O366) -> #DIV/0!
A367: 532 | B367: Ba | C367: 131 | D367: 56 | E367: 75 | F367: 8.733037 | H367: =IF(B367=$H$1,COUNT($H$2:H368)+1," ") | L367: 366 | M367: 55 | N367: 82 | O367: 8.703047 | P367: =N367+M367 -> 137 | Q367: =INDEX(Elemek!$B$2:$B$113,MATCH(M367,Elemek!$C$2:$C$113,0)) -> Cs | R367: =IF(NOT(ISBLANK(O367)),O367,ROUNDDOWN(AVERAGE($O$2:$O$990),2)) -> 8.703047 | S367: =IF(ISBLANK(O367),ROUNDDOWN(AVERAGEIF($M$2:$M$990,M367,$O$2:$O$990),2),O367) -> 8.703047
A368: 767 | B368: Sb | C368: 128 | D368: 51 | E368: 77 | F368: 8.732343 | H368: =IF(B368=$H$1,COUNT($H$2:H369)+1," ") | L368: 367 | M368: 96 | N368: 147 | O368: 7.836004 | P368: =N368+M368 -> 243 | Q368: =INDEX(Elemek!$B$2:$B$113,MATCH(M368,Elemek!$C$2:$C$113,0)) -> Cm | R368: =IF(NOT(ISBLANK(O368)),O368,ROUNDDOWN(AVERAGE($O$2:$O$990),2)) -> 7.836004 | S368: =IF(ISBLANK(O368),ROUNDDOWN(AVERAGEIF($M$2:$M$990,M368,$O$2:$O$990),2),O368) -> 7.836004
A369: 558 | B369: Cs | C369: 132 | D369: 55 | E369: 77 | F369: 8.731599 | H369: =IF(B369=$H$1,COUNT($H$2:H370)+1," ") | L369: 368 | M369: 38 | N369: 52 | O369: 9.026239 | P369: =N369+M369 -> 90 | Q369: =INDEX(Elemek!$B$2:$B$113,MATCH(M369,Elemek!$C$2:$C$113,0)) -> Sr | R369: =IF(NOT(ISBLANK(O369)),O369,ROUNDDOWN(AVERAGE($O$2:$O$990),2)) -> 9.026239 | S369: =IF(ISBLANK(O369),ROUNDDOWN(AVERAGEIF($M$2:$M$990,M369,$O$2:$O$990),2),O369) -> 9.026239
A370: 899 | B370: Ba | C370: 129 | D370: 56 | E370: 73 | F370: 8.730746 | H370: =IF(B370=$H$1,COUNT($H$2:H371)+1," ") | L370: 369 | M370: 82 | N370: 128 | O370: 8.141462 | P370: =N370+M370 -> 210 | Q370: =INDEX(Elemek!$B$2:$B$113,MATCH(M370,Elemek!$C$2:$C$113,0)) -> Pb | R370: =IF(NOT(ISBLANK(O370)),O370,ROUNDDOWN(AVERAGE($O$2:$O$990),2)) -> 8.141462 | S370: =IF(ISBLANK(O370),ROUNDDOWN(AVERAGEIF($M$2:$M$990,M370,$O$2:$O$990),2),O370) -> 8.141462
A371: 569 | B371: Xe | C371: 133 | D371: 54 | E371: 79 | F371: 8.730302 | H371: =IF(B371=$H$1,COUNT($H$2:H372)+1," ") | L371: 370 | M371: 89 | N371: 138 | O371: 7.957447 | P371: =N371+M371 -> 227 | Q371: =INDEX(Elemek!$B$2:$B$113,MATCH(M371,Elemek!$C$2:$C$113,0)) -> Ac | R371: =IF(NOT(ISBLANK(O371)),O371,ROUNDDOWN(AVERAGE($O$2:$O$990),2)) -> 7.957447 | S371: =IF(ISBLANK(O371),ROUNDDOWN(AVERAGEIF($M$2:$M$990,M371,$O$2:$O$990),2),O371) -> 7.957447
A372: 380 | B372: Ba | C372: 133 | D372: 56 | E372: 77 | F372: 8.729624 | H372: =IF(B372=$H$1,COUNT($H$2:H373)+1," ") | L372: 371 | M372: 96 | N372: 148 | O372: 7.831763 | P372: =N372+M372 -> 244 | Q372: =INDEX(Elemek!$B$2:$B$113,MATCH(M372,Elemek!$C$2:$C$113,0)) -> Cm | R372: =IF(NOT(ISBLANK(O372)),O372,ROUNDDOWN(AVERAGE($O$2:$O$990),2)) -> 7.831763 | S372: =IF(ISBLANK(O372),ROUNDDOWN(AVERAGEIF($M$2:$M$990,M372,$O$2:$O$990),2),O372) -> 7.831763
A373: 196 | B373: Xe | C373: 134 | D373: 54 | E373: 80 | F373: 8.728973 | H373: =IF(B373=$H$1,COUNT($H$2:H374)+1," ") | L373: 372 | M373: 61 | N373: 84 | O373: 8.631838 | P373: =N373+M373 -> 145 | Q373: =INDEX(Elemek!$B$2:$B$113,MATCH(M373,Elemek!$C$2:$C$113,0)) -> Pm | R373: =IF(NOT(ISBLANK(O373)),O373,ROUNDDOWN(AVERAGE($O$2:$O$990),2)) -> 8.631838 | S373: =IF(ISBLANK(O373),ROUNDDOWN(AVERAGEIF($M$2:$M$990,M373,$O$2:$O$990),2),O373) -> 8.631838
A374: 906 | B374: Sn | C374: 127 | D374: 50 | E374: 77 | F374: 8.7288 | H374: =IF(B374=$H$1,COUNT($H$2:H375)+1," ") | L374: 373 | M374: 41 | N374: 52 | P374: =N374+M374 -> 93 | Q374: =INDEX(Elemek!$B$2:$B$113,MATCH(M374,Elemek!$C$2:$C$113,0)) -> Nb | R374: =IF(NOT(ISBLANK(O374)),O374,ROUNDDOWN(AVERAGE($O$2:$O$990),2)) -> #DIV/0! | S374: =IF(ISBLANK(O374),ROUNDDOWN(AVERAGEIF($M$2:$M$990,M374,$O$2:$O$990),2),O374) -> #DIV/0!
A375: 933 | B375: Ba | C375: 126 | D375: 56 | E375: 70 | F375: 8.727439 | H375: =IF(B375=$H$1,COUNT($H$2:H376)+1," ") | L375: 374 | M375: 94 | N375: 147 | O375: 7.85159 | P375: =N375+M375 -> 241 | Q375: =INDEX(Elemek!$B$2:$B$113,MATCH(M375,Elemek!$C$2:$C$113,0)) -> Pu | R375: =IF(NOT(ISBLANK(O375)),O375,ROUNDDOWN(AVERAGE($O$2:$O$990),2)) -> 7.85159 | S375: =IF(ISBLANK(O375),ROUNDDOWN(AVERAGEIF($M$2:$M$990,M375,$O$2:$O$990),2),O375) -> 7.85159
A376: 829 | B376: Sb | C376: 129 | D376: 51 | E376: 78 | F376: 8.727358 | H376: =IF(B376=$H$1,COUNT($H$2:H377)+1," ") | L376: 375 | M376: 48 | N376: 65 | P376: =N376+M376 -> 113 | Q376: =INDEX(Elemek!$B$2:$B$113,MATCH(M376,Elemek!$C$2:$C$113,0)) -> Cd | R376: =IF(NOT(ISBLANK(O376)),O376,ROUNDDOWN(AVERAGE($O$2:$O$990),2)) -> #DIV/0! | S376: =IF(ISBLANK(O376),ROUNDDOWN(AVERAGEIF($M$2:$M$990,M376,$O$2:$O$990),2),O376) -> #DIV/0!
A377: 108 | B377: Ba | C377: 136 | D377: 56 | E377: 80 | F377: 8.724908 | H377: =IF(B377=$H$1,COUNT($H$2:H378)+1," ") | L377: 376 | M377: 63 | N377: 89 | O377: 8.550897 | P377: =N377+M377 -> 152 | Q377: =INDEX(Elemek!$B$2:$B$113,MATCH(M377,Elemek!$C$2:$C$113,0)) -> Eu | R377: =IF(NOT(ISBLANK(O377)),O377,ROUNDDOWN(AVERAGE($O$2:$O$990),2)) -> 8.550897 | S377: =IF(ISBLANK(O377),ROUNDDOWN(AVERAGEIF($M$2:$M$990,M377,$O$2:$O$990),2),O377) -> 8.550897
A378: 109 | B378: Ba | C378: 135 | D378: 56 | E378: 79 | F378: 8.722072 | H378: =IF(B378=$H$1,COUNT($H$2:H379)+1," ") | L378: 377 | M378: 98 | N378: 152 | O378: 7.78664 | P378: =N378+M378 -> 250 | Q378: =INDEX(Elemek!$B$2:$B$113,MATCH(M378,Elemek!$C$2:$C$113,0)) -> Cf | R378: =IF(NOT(ISBLANK(O378)),O378,ROUNDDOWN(AVERAGE($O$2:$O$990),2)) -> 7.78664 | S378: =IF(ISBLANK(O378),ROUNDDOWN(AVERAGEIF($M$2:$M$990,M378,$O$2:$O$990),2),O378) -> 7.78664
A379: 896 | B379: I | C379: 132 | D379: 53 | E379: 79 | F379: 8.72057 | H379: =IF(B379=$H$1,COUNT($H$2:H380)+1," ") | L379: 378 | M379: 1 | N379: 2 | O379: 3.087994 | P379: =N379+M379 -> 3 | Q379: =INDEX(Elemek!$B$2:$B$113,MATCH(M379,Elemek!$C$2:$C$113,0)) -> H | R379: =IF(NOT(ISBLANK(O379)),O379,ROUNDDOWN(AVERAGE($O$2:$O$990),2)) -> 3.087994 | S379: =IF(ISBLANK(O379),ROUNDDOWN(AVERAGEIF($M$2:$M$990,M379,$O$2:$O$990),2),O379) -> 3.087994
A380: 662 | B380: Te | C380: 131 | D380: 52 | E380: 79 | F380: 8.720392 | H380: =IF(B380=$H$1,COUNT($H$2:H381)+1," ") | L380: 379 | M380: 36 | N380: 49 | O380: 9.029919 | P380: =N380+M380 -> 85 | Q380: =INDEX(Elemek!$B$2:$B$113,MATCH(M380,Elemek!$C$2:$C$113,0)) -> Kr | R380: =IF(NOT(ISBLANK(O380)),O380,ROUNDDOWN(AVERAGE($O$2:$O$990),2)) -> 9.029919 | S380: =IF(ISBLANK(O380),ROUNDDOWN(AVERAGEIF($M$2:$M$990,M380,$O$2:$O$990),2),O380) -> 9.029919
A381: 306 | B381: Cs | C381: 135 | D381: 55 | E381: 80 | F381: 8.720082 | H381: =IF(B381=$H$1,COUNT($H$2:H382)+1," ") | L381: 380 | M381: 56 | N381: 77 | O381: 8.729624 | P381: =N381+M381 -> 133 | Q381: =INDEX(Elemek!$B$2:$B$113,MATCH(M381,Elemek!$C$2:$C$113,0)) -> Ba | R381: =IF(NOT(ISBLANK(O381)),O381,ROUNDDOWN(AVERAGE($O$2:$O$990),2)) -> 8.729624 | S381: =IF(ISBLANK(O381),ROUNDDOWN(AVERAGEIF($M$2:$M$990,M381,$O$2:$O$990),2),O381) -> 8.729624
A382: 398 | B382: Cs | C382: 134 | D382: 55 | E382: 79 | F382: 8.719768 | H382: =IF(B382=$H$1,COUNT($H$2:H383)+1," ") | L382: 381 | M382: 63 | N382: 91 | O382: 8.5372 | P382: =N382+M382 -> 154 | Q382: =INDEX(Elemek!$B$2:$B$113,MATCH(M382,Elemek!$C$2:$C$113,0)) -> Eu | R382: =IF(NOT(ISBLANK(O382)),O382,ROUNDDOWN(AVERAGE($O$2:$O$990),2)) -> 8.5372 | S382: =IF(ISBLANK(O382),ROUNDDOWN(AVERAGEIF($M$2:$M$990,M382,$O$2:$O$990),2),O382) -> 8.5372
A383: 692 | B383: I | C383: 133 | D383: 53 | E383: 80 | F383: 8.717094 | H383: =IF(B383=$H$1,COUNT($H$2:H384)+1," ") | L383: 382 | M383: 76 | N383: 118 | O383: 8.238508 | P383: =N383+M383 -> 194 | Q383: =INDEX(Elemek!$B$2:$B$113,MATCH(M383,Elemek!$C$2:$C$113,0)) -> Os | R383: =IF(NOT(ISBLANK(O383)),O383,ROUNDDOWN(AVERAGE($O$2:$O$990),2)) -> 8.238508 | S383: =IF(ISBLANK(O383),ROUNDDOWN(AVERAGEIF($M$2:$M$990,M383,$O$2:$O$990),2),O383) -> 8.238508
A384: 596 | B384: Te | C384: 132 | D384: 52 | E384: 80 | F384: 8.716646 | H384: =IF(B384=$H$1,COUNT($H$2:H385)+1," ") | L384: 383 | M384: 88 | N384: 140 | O384: 7.94439 | P384: =N384+M384 -> 228 | Q384: =INDEX(Elemek!$B$2:$B$113,MATCH(M384,Elemek!$C$2:$C$113,0)) -> Ra | R384: =IF(NOT(ISBLANK(O384)),O384,ROUNDDOWN(AVERAGE($O$2:$O$990),2)) -> 7.94439 | S384: =IF(ISBLANK(O384),ROUNDDOWN(AVERAGEIF($M$2:$M$990,M384,$O$2:$O$990),2),O384) -> 7.94439
A385: 838 | B385: La | C385: 133 | D385: 57 | E385: 76 | F385: 8.714109 | H385: =IF(B385=$H$1,COUNT($H$2:H386)+1," ") | L385: 384 | M385: 61 | N385: 85 | O385: 8.615574 | P385: =N385+M385 -> 146 | Q385: =INDEX(Elemek!$B$2:$B$113,MATCH(M385,Elemek!$C$2:$C$113,0)) -> Pm | R385: =IF(NOT(ISBLANK(O385)),O385,ROUNDDOWN(AVERAGE($O$2:$O$990),2)) -> 8.615574 | S385: =IF(ISBLANK(O385),ROUNDDOWN(AVERAGEIF($M$2:$M$990,M385,$O$2:$O$990),2),O385) -> 8.615574
A386: 698 | B386: La | C386: 135 | D386: 57 | E386: 78 | F386: 8.713179 | H386: =IF(B386=$H$1,COUNT($H$2:H387)+1," ") | L386: 385 | M386: 27 | N386: 33 | O386: 9.098811 | P386: =N386+M386 -> 60 | Q386: =INDEX(Elemek!$B$2:$B$113,MATCH(M386,Elemek!$C$2:$C$113,0)) -> Co | R386: =IF(NOT(ISBLANK(O386)),O386,ROUNDDOWN(AVERAGE($O$2:$O$990),2)) -> 9.098811 | S386: =IF(ISBLANK(O386),ROUNDDOWN(AVERAGEIF($M$2:$M$990,M386,$O$2:$O$990),2),O386) -> 9.098811
A387: 110 | B387: Ba | C387: 137 | D387: 56 | E387: 81 | F387: 8.711628 | H387: =IF(B387=$H$1,COUNT($H$2:H388)+1," ") | L387: 386 | M387: 63 | N387: 92 | O387: 8.534711 | P387: =N387+M387 -> 155 | Q387: =INDEX(Elemek!$B$2:$B$113,MATCH(M387,Elemek!$C$2:$C$113,0)) -> Eu | R387: =IF(NOT(ISBLANK(O387)),O387,ROUNDDOWN(AVERAGE($O$2:$O$990),2)) -> 8.534711 | S387: =IF(ISBLANK(O387),ROUNDDOWN(AVERAGEIF($M$2:$M$990,M387,$O$2:$O$990),2),O387) -> 8.534711
A388: 765 | B388: Xe | C388: 135 | D388: 54 | E388: 81 | F388: 8.711453 | H388: =IF(B388=$H$1,COUNT($H$2:H389)+1," ") | L388: 387 | M388: 81 | N388: 123 | O388: 8.190671 | P388: =N388+M388 -> 204 | Q388: =INDEX(Elemek!$B$2:$B$113,MATCH(M388,Elemek!$C$2:$C$113,0)) -> Tl | R388: =IF(NOT(ISBLANK(O388)),O388,ROUNDDOWN(AVERAGE($O$2:$O$990),2)) -> 8.190671 | S388: =IF(ISBLANK(O388),ROUNDDOWN(AVERAGEIF($M$2:$M$990,M388,$O$2:$O$990),2),O388) -> 8.190671
... A414: 117 | B414: Nd | C414: 142 | D414: 60 | E414: 82 | F414: 8.676646 | H414: =IF(B414=$H$1,COUNT($H$2:H415)+1," ") | L414: 413 | M414: 25 | N414: 29 | O414: 9.100131 | P414: =N414+M414 -> 54 | Q414: =INDEX(Elemek!$B$2:$B$113,MATCH(M414,Elemek!$C$2:$C$113,0)) -> Mn | R414: =IF(NOT(ISBLANK(O414)),O414,ROUNDDOWN(AVERAGE($O$2:$O$990),2)) -> 9.100131 | S414: =IF(ISBLANK(O414),ROUNDDOWN(AVERAGEIF($M$2:$M$990,M414,$O$2:$O$990),2),O414) -> 9.100131
A415: 638 | B415: La | C415: 140 | D415: 57 | E415: 83 | F415: 8.67362 | H415: =IF(B415=$H$1,COUNT($H$2:H416)+1," ") | L415: 414 | M415: 50 | N415: 69 | P415: =N415+M415 -> 119 | Q415: =INDEX(Elemek!$B$2:$B$113,MATCH(M415,Elemek!$C$2:$C$113,0)) -> Sn | R415: =IF(NOT(ISBLANK(O415)),O415,ROUNDDOWN(AVERAGE($O$2:$O$990),2)) -> #DIV/0! | S415: =IF(ISBLANK(O415),ROUNDDOWN(AVERAGEIF($M$2:$M$990,M415,$O$2:$O$990),2),O415) -> #DIV/0!
A416: 591 | B416: Nd | C416: 140 | D416: 60 | E416: 80 | F416: 8.673113 | H416: =IF(B416=$H$1,COUNT($H$2:H417)+1," ") | L416: 415 | M416: 58 | N416: 86 | O416: 8.629918 | P416: =N416+M416 -> 144 | Q416: =INDEX(Elemek!$B$2:$B$113,MATCH(M416,Elemek!$C$2:$C$113,0)) -> Ce | R416: =IF(NOT(ISBLANK(O416)),O416,ROUNDDOWN(AVERAGE($O$2:$O$990),2)) -> 8.629918 | S416: =IF(ISBLANK(O416),ROUNDDOWN(AVERAGEIF($M$2:$M$990,M416,$O$2:$O$990),2),O416) -> 8.629918
...
