Workbook

Sheet Francia egyetemek QS rangsora
A1: Egyetem neve | B1: Méret | C1: Kutatás | D1: Életkor | E1: Státusz | F1: 2013 | G1: 2014 | H1: 2015 | I1: 2016 | J1: 2017 | K1: 2018 | L1: 2019 | M1: 2020 | N1: Legjobb év | R1: =MAX(R2:R50) -> 23
A2: CentraleSupélec | B2: S | C2: VH | D2: 5 | E2: A | F2: - | G2: - | H2: 60.1 | I2: 52.1 | J2: =IFERROR(ROUND(F2:I2,1),"-") -> - | K2: 50 | L2: 51.5 | M2: 51.4 | N2: =IFERROR(INDEX($F$1:$M$1,MATCH(MAX(F2:M2),F2:M2,0)),"Nincs ilyen!") -> 2015 | R2: =MAX(F2:M2)-MIN(F2:M2) -> 10.1
A3: Ecole des Ponts ParisTech | B3: S | C3: HI | D3: 5 | E3: A | F3: 40.2 | G3: 42.2 | H3: 41.1 | I3: 39.1 | J3: =IFERROR(ROUND(F3:I3,1),"-") -> - | K3: 39.8 | L3: 37 | M3: 37.8 | N3: =IFERROR(INDEX($F$1:$M$1,MATCH(MAX(F3:M3),F3:M3,0)),"Nincs ilyen!") -> 2014 | R3: =MAX(F3:M3)-MIN(F3:M3) -> 5.2
A4: Ecole Normale Supérieure de Lyon | B4: S | C4: VH | D4: 5 | E4: A | F4: 57.7 | G4: 56.3 | H4: 55.1 | I4: 49.6 | J4: =IFERROR(ROUND(F4:I4,1),"-") -> - | K4: 52.8 | L4: 49.2 | M4: 48.3 | N4: =IFERROR(INDEX($F$1:$M$1,MATCH(MAX(F4:M4),F4:M4,0)),"Nincs ilyen!") -> 2013 | R4: =MAX(F4:M4)-MIN(F4:M4) -> 9.4
A5: Ecole Normale Supérieure, Paris (ENS Paris) | B5: S | C5: VH | D5: 5 | E5: B | F5: 87.8 | G5: 90.2 | H5: 89.2 | I5: 82.9 | J5: =IFERROR(ROUND(F5:I5,1),"-") -> - | K5: 79.9 | L5: - | M5: - | N5: =IFERROR(INDEX($F$1:$M$1,MATCH(MAX(F5:M5),F5:M5,0)),"Nincs ilyen!") -> 2014 | R5: =MAX(F5:M5)-MIN(F5:M5) -> 10.3
A6: Ecole Polytechnique | B6: S | C6: VH | D6: 5 | E6: A | F6: 81.1 | G6: 85 | H6: 83.8 | I6: 75.7 | J6: =IFERROR(ROUND(F6:I6,1),"-") -> - | K6: 74 | L6: 67.9 | M6: 70.5 | N6: =IFERROR(INDEX($F$1:$M$1,MATCH(MAX(F6:M6),F6:M6,0)),"Nincs ilyen!") -> 2014 | R6: =MAX(F6:M6)-MIN(F6:M6) -> 17.1
A7: ENS Paris-Saclay | B7: S | C7: VH | D7: 5 | E7: A | F7: 38 | G7: 39.2 | H7: 42.8 | I7: 39.2 | J7: =IFERROR(ROUND(F7:I7,1),"-") -> - | K7: 35.4 | L7: 34.3 | M7: 33.5 | N7: =IFERROR(INDEX($F$1:$M$1,MATCH(MAX(F7:M7),F7:M7,0)),"Nincs ilyen!") -> 2015 | R7: =MAX(F7:M7)-MIN(F7:M7) -> 9.3
A8: ESCP Europe | B8: S | C8: MD | D8: 5 | E8: B | F8: - | G8: - | H8: - | I8: - | J8: =IFERROR(ROUND(F8:I8,1),"-") -> - | K8: - | L8: - | M8: - | N8: =IFERROR(INDEX($F$1:$M$1,MATCH(MAX(F8:M8),F8:M8,0)),"Nincs ilyen!") -> Nincs ilyen! | R8: =MAX(F8:M8)-MIN(F8:M8) -> 0
A9: ESSEC Business School, Paris | B9: M | C9: VH | D9: 5 | E9: B | F9: - | G9: - | H9: - | I9: - | J9: =IFERROR(ROUND(F9:I9,1),"-") -> - | K9: - | L9: - | M9: - | N9: =IFERROR(INDEX($F$1:$M$1,MATCH(MAX(F9:M9),F9:M9,0)),"Nincs ilyen!") -> Nincs ilyen! | R9: =MAX(F9:M9)-MIN(F9:M9) -> 0
A10: Grenoble INP, Grenoble Institute of Technology | B10: M | C10: HI | D10: 5 | E10: A | F10: - | G10: - | H10: - | I10: - | J10: =IFERROR(ROUND(F10:I10,1),"-") -> - | K10: - | L10: - | M10: - | N10: =IFERROR(INDEX($F$1:$M$1,MATCH(MAX(F10:M10),F10:M10,0)),"Nincs ilyen!") -> Nincs ilyen! | R10: =MAX(F10:M10)-MIN(F10:M10) -> 0
A11: HEC Paris | B11: S | C11: VH | D11: 5 | E11: B | F11: - | G11: - | H11: - | I11: - | J11: =IFERROR(ROUND(F11:I11,1),"-") -> - | K11: - | L11: - | M11: - | N11: =IFERROR(INDEX($F$1:$M$1,MATCH(MAX(F11:M11),F11:M11,0)),"Nincs ilyen!") -> Nincs ilyen! | R11: =MAX(F11:M11)-MIN(F11:M11) -> 0
A12: INSEAD (France) | B12: S | C12: VH | D12: 4 | E12: B | F12: - | G12: - | H12: - | I12: - | J12: =IFERROR(ROUND(F12:I12,1),"-") -> - | K12: - | L12: - | M12: - | N12: =IFERROR(INDEX($F$1:$M$1,MATCH(MAX(F12:M12),F12:M12,0)),"Nincs ilyen!") -> Nincs ilyen! | R12: =MAX(F12:M12)-MIN(F12:M12) -> 0
A13: Institut National des Sciences Appliquées de Lyon (INSA) | B13: M | C13: VH | D13: 4 | F13: - | G13: 34.3 | H13: 35.9 | I13: 28.5 | J13: =IFERROR(ROUND(F13:I13,1),"-") -> - | K13: 27.7 | L13: 24.6 | M13: 23.8 | N13: =IFERROR(INDEX($F$1:$M$1,MATCH(MAX(F13:M13),F13:M13,0)),"Nincs ilyen!") -> 2015 | R13: =MAX(F13:M13)-MIN(F13:M13) -> 12.1
A14: Sciences Po Paris | B14: M | C14: HI | D14: 5 | E14: A | F14: 50.2 | G14: 50.7 | H14: 50.2 | I14: 44.5 | J14: =IFERROR(ROUND(F14:I14,1),"-") -> - | K14: 45.2 | L14: 41 | M14: 38.9 | N14: =IFERROR(INDEX($F$1:$M$1,MATCH(MAX(F14:M14),F14:M14,0)),"Nincs ilyen!") -> 2014 | R14: =MAX(F14:M14)-MIN(F14:M14) -> 11.8
A15: Sorbonne University | B15: XL | C15: VH | D15: 1 | E15: A | F15: - | G15: - | H15: - | I15: - | J15: =IFERROR(ROUND(F15:I15,1),"-") -> - | K15: - | L15: 64.8 | M15: 64.9 | N15: =IFERROR(INDEX($F$1:$M$1,MATCH(MAX(F15:M15),F15:M15,0)),"Nincs ilyen!") -> 2020 | R15: =MAX(F15:M15)-MIN(F15:M15) -> 0.1
A16: TELECOM ParisTech | B16: S | C16: HI | D16: 1 | F16: - | G16: - | H16: - | I16: - | J16: =IFERROR(ROUND(F16:I16,1),"-") -> - | K16: - | L16: - | M16: 40.7 | N16: =IFERROR(INDEX($F$1:$M$1,MATCH(MAX(F16:M16),F16:M16,0)),"Nincs ilyen!") -> 2020 | R16: =MAX(F16:M16)-MIN(F16:M16) -> 0
A17: Université Aix-Marseille | B17: XL | C17: VH | D17: 5 | E17: A | F17: 36 | G17: 39.1 | H17: 37.5 | I17: 28.9 | J17: =IFERROR(ROUND(F17:I17,1),"-") -> - | K17: 29.7 | L17: 25.6 | M17: 24.3 | N17: =IFERROR(INDEX($F$1:$M$1,MATCH(MAX(F17:M17),F17:M17,0)),"Nincs ilyen!") -> 2014 | R17: =MAX(F17:M17)-MIN(F17:M17) -> 14.8
A18: Université Claude Bernard Lyon 1 | B18: XL | C18: HI | D18: 5 | E18: A | F18: 32.4 | G18: 34.6 | H18: 30.2 | I18: - | J18: =IFERROR(ROUND(F18:I18,1),"-") -> - | K18: - | L18: 19.2 | M18: 17.5 | N18: =IFERROR(INDEX($F$1:$M$1,MATCH(MAX(F18:M18),F18:M18,0)),"Nincs ilyen!") -> 2014 | R18: =MAX(F18:M18)-MIN(F18:M18) -> 17.1
A19: Université de Bordeaux | B19: XL | C19: VH | D19: 5 | E19: A | F19: 39.4 | G19: 37.3 | H19: 32 | I19: - | J19: =IFERROR(ROUND(F19:I19,1),"-") -> - | K19: - | L19: 24 | M19: 25.5 | N19: =IFERROR(INDEX($F$1:$M$1,MATCH(MAX(F19:M19),F19:M19,0)),"Nincs ilyen!") -> 2013 | R19: =MAX(F19:M19)-MIN(F19:M19) -> 15.4
A20: Université de Caen Basse-Normandie | B20: L | C20: HI | D20: 5 | E20: A | F20: - | G20: - | H20: - | I20: - | J20: =IFERROR(ROUND(F20:I20,1),"-") -> - | K20: - | L20: 10.7 | M20: - | N20: =IFERROR(INDEX($F$1:$M$1,MATCH(MAX(F20:M20),F20:M20,0)),"Nincs ilyen!") -> 2019 | R20: =MAX(F20:M20)-MIN(F20:M20) -> 0
A21: Université de Cergy-Pontoise | B21: L | C21: MD | D21: 2 | E21: A | F21: - | G21: - | H21: - | I21: - | J21: =IFERROR(ROUND(F21:I21,1),"-") -> - | K21: - | L21: 10.7 | M21: - | N21: =IFERROR(INDEX($F$1:$M$1,MATCH(MAX(F21:M21),F21:M21,0)),"Nincs ilyen!") -> 2019 | R21: =MAX(F21:M21)-MIN(F21:M21) -> 0
A22: Université de Lille | B22: XL | C22: VH | D22: 1 | E22: A | F22: 32.6 | G22: 30 | H22: 30.5 | I22: - | J22: =IFERROR(ROUND(F22:I22,1),"-") -> - | K22: - | L22: 17.9 | M22: 15.9 | N22: =IFERROR(INDEX($F$1:$M$1,MATCH(MAX(F22:M22),F22:M22,0)),"Nincs ilyen!") -> 2013 | R22: =MAX(F22:M22)-MIN(F22:M22) -> 16.7
A23: Université de Lorraine | B23: XL | C23: MD | D23: 5 | E23: A | F23: - | G23: - | H23: - | I23: - | J23: =IFERROR(ROUND(F23:I23,1),"-") -> - | K23: - | L23: 10.7 | M23: 14.6 | N23: =IFERROR(INDEX($F$1:$M$1,MATCH(MAX(F23:M23),F23:M23,0)),"Nincs ilyen!") -> 2020 | R23: =MAX(F23:M23)-MIN(F23:M23) -> 3.9
A24: Université de Montpellier | B24: XL | C24: VH | D24: 5 | E24: A | F24: 33.9 | G24: 33.3 | H24: 36.4 | I24: 34.8 | J24: =IFERROR(ROUND(F24:I24,1),"-") -> - | K24: 32 | L24: 27 | M24: 24.2 | N24: =IFERROR(INDEX($F$1:$M$1,MATCH(MAX(F24:M24),F24:M24,0)),"Nincs ilyen!") -> 2015 | R24: =MAX(F24:M24)-MIN(F24:M24) -> 12.2
A25: Université de Nantes | B25: XL | C25: HI | D25: 5 | E25: A | F25: - | G25: - | H25: - | I25: - | J25: =IFERROR(ROUND(F25:I25,1),"-") -> - | K25: - | L25: 10.7 | M25: 11.5 | N25: =IFERROR(INDEX($F$1:$M$1,MATCH(MAX(F25:M25),F25:M25,0)),"Nincs ilyen!") -> 2020 | R25: =MAX(F25:M25)-MIN(F25:M25) -> 0.8
A26: Université de Poitiers | B26: L | C26: HI | D26: 5 | E26: A | F26: - | G26: - | H26: - | I26: - | J26: =IFERROR(ROUND(F26:I26,1),"-") -> - | K26: - | L26: 10.7 | M26: 11.5 | N26: =IFERROR(INDEX($F$1:$M$1,MATCH(MAX(F26:M26),F26:M26,0)),"Nincs ilyen!") -> 2020 | R26: =MAX(F26:M26)-MIN(F26:M26) -> 0.8
A27: Université de Rennes 1 | B27: L | C27: VH | D27: 5 | E27: A | F27: - | G27: - | H27: - | I27: - | J27: =IFERROR(ROUND(F27:I27,1),"-") -> - | K27: - | L27: 16.2 | M27: 11.5 | N27: =IFERROR(INDEX($F$1:$M$1,MATCH(MAX(F27:M27),F27:M27,0)),"Nincs ilyen!") -> 2019 | R27: =MAX(F27:M27)-MIN(F27:M27) -> 4.7
A28: Université de Strasbourg | B28: XL | C28: HI | D28: 5 | E28: A | F28: 48.5 | G28: 50.4 | H28: 48.1 | I28: 39.6 | J28: =IFERROR(ROUND(F28:I28,1),"-") -> - | K28: 37.5 | L28: 31.3 | M28: 28.9 | N28: =IFERROR(INDEX($F$1:$M$1,MATCH(MAX(F28:M28),F28:M28,0)),"Nincs ilyen!") -> 2014 | R28: =MAX(F28:M28)-MIN(F28:M28) -> 21.5
A29: Université de Technologie, Compiègne (UTC) | B29: S | C29: VH | D29: 3 | E29: A | F29: - | G29: - | H29: - | I29: - | J29: =IFERROR(ROUND(F29:I29,1),"-") -> - | K29: - | L29: - | M29: - | N29: =IFERROR(INDEX($F$1:$M$1,MATCH(MAX(F29:M29),F29:M29,0)),"Nincs ilyen!") -> Nincs ilyen! | R29: =MAX(F29:M29)-MIN(F29:M29) -> 0
A30: Université Grenoble-Alpes (UGA) | B30: XL | C30: VH | D30: 5 | E30: A | F30: 49.6 | G30: 51.8 | H30: 48.9 | I30: 46.1 | J30: =IFERROR(ROUND(F30:I30,1),"-") -> - | K30: 42.9 | L30: 35 | M30: 31 | N30: =IFERROR(INDEX($F$1:$M$1,MATCH(MAX(F30:M30),F30:M30,0)),"Nincs ilyen!") -> 2014 | R30: =MAX(F30:M30)-MIN(F30:M30) -> 20.8
A31: Université Jean Moulin Lyon 3 | B31: L | C31: LO | D31: 5 | E31: A | F31: - | G31: - | H31: - | I31: - | J31: =IFERROR(ROUND(F31:I31,1),"-") -> - | K31: - | L31: 10.7 | M31: - | N31: =IFERROR(INDEX($F$1:$M$1,MATCH(MAX(F31:M31),F31:M31,0)),"Nincs ilyen!") -> 2019 | R31: =MAX(F31:M31)-MIN(F31:M31) -> 0
A32: Université Lumière Lyon 2 | B32: L | C32: HI | D32: 5 | E32: A | F32: - | G32: - | H32: - | I32: - | J32: =IFERROR(ROUND(F32:I32,1),"-") -> - | K32: - | L32: 10.7 | M32: 11.5 | N32: =IFERROR(INDEX($F$1:$M$1,MATCH(MAX(F32:M32),F32:M32,0)),"Nincs ilyen!") -> 2020 | R32: =MAX(F32:M32)-MIN(F32:M32) -> 0.8
A33: Université Nice Sophia-Antipolis | B33: L | C33: HI | D33: 3 | E33: A | F33: 28.5 | G33: - | H33: - | I33: - | J33: =IFERROR(ROUND(F33:I33,1),"-") -> - | K33: - | L33: 17.9 | M33: - | N33: =IFERROR(INDEX($F$1:$M$1,MATCH(MAX(F33:M33),F33:M33,0)),"Nincs ilyen!") -> 2013 | R33: =MAX(F33:M33)-MIN(F33:M33) -> 10.6
A34: Université Panthéon-Assas (Paris 2) | B34: L | C34: LO | D34: 5 | E34: A | F34: 30.3 | G34: - | H34: - | I34: - | J34: =IFERROR(ROUND(F34:I34,1),"-") -> - | K34: - | L34: 22.3 | M34: 22.1 | N34: =IFERROR(INDEX($F$1:$M$1,MATCH(MAX(F34:M34),F34:M34,0)),"Nincs ilyen!") -> 2013 | R34: =MAX(F34:M34)-MIN(F34:M34) -> 8.2
A35: Université Paris 1 Panthéon-Sorbonne | B35: XL | C35: HI | D35: 5 | E35: A | F35: 49.1 | G35: 50 | H35: 48.2 | I35: 43.3 | J35: =IFERROR(ROUND(F35:I35,1),"-") -> - | K35: 40 | L35: 34.5 | M35: 34.2 | N35: =IFERROR(INDEX($F$1:$M$1,MATCH(MAX(F35:M35),F35:M35,0)),"Nincs ilyen!") -> 2014 | R35: =MAX(F35:M35)-MIN(F35:M35) -> 15.8
A36: Université Paris Dauphine | B36: M | C36: MD | D36: 3 | E36: A | F36: 35.9 | G36: 36.9 | H36: 36.9 | I36: 32.8 | J36: =IFERROR(ROUND(F36:I36,1),"-") -> - | K36: 33.4 | L36: - | M36: - | N36: =IFERROR(INDEX($F$1:$M$1,MATCH(MAX(F36:M36),F36:M36,0)),"Nincs ilyen!") -> 2014 | R36: =MAX(F36:M36)-MIN(F36:M36) -> 4.1
A37: Université Paris Descartes | B37: L | C37: VH | D37: 5 | E37: A | F37: 42.2 | G37: 44 | H37: 35.9 | I37: 31.4 | J37: =IFERROR(ROUND(F37:I37,1),"-") -> - | K37: 27.9 | L37: 21 | M37: - | N37: =IFERROR(INDEX($F$1:$M$1,MATCH(MAX(F37:M37),F37:M37,0)),"Nincs ilyen!") -> 2014 | R37: =MAX(F37:M37)-MIN(F37:M37) -> 23
A38: Université Paris Diderot - Paris 7 | B38: L | C38: VH | D38: 5 | E38: A | F38: 51.8 | G38: 53 | H38: 46 | I38: 39.4 | J38: =IFERROR(ROUND(F38:I38,1),"-") -> - | K38: 37.3 | L38: 34.7 | M38: - | N38: =IFERROR(INDEX($F$1:$M$1,MATCH(MAX(F38:M38),F38:M38,0)),"Nincs ilyen!") -> 2014 | R38: =MAX(F38:M38)-MIN(F38:M38) -> 18.3
A39: Université Paris Ouest Nanterre La Défense | B39: L | C39: HI | D39: 5 | E39: A | F39: - | G39: - | H39: - | I39: - | J39: =IFERROR(ROUND(F39:I39,1),"-") -> - | K39: - | L39: 10.7 | M39: - | N39: =IFERROR(INDEX($F$1:$M$1,MATCH(MAX(F39:M39),F39:M39,0)),"Nincs ilyen!") -> 2019 | R39: =MAX(F39:M39)-MIN(F39:M39) -> 0
A40: Université Paris-Sorbonne (Paris IV) | B40: L | C40: VH | D40: 5 | E40: A | F40: 49.9 | G40: 50.3 | H40: 50.3 | I40: 44.4 | J40: =IFERROR(ROUND(F40:I40,1),"-") -> - | K40: 37.9 | L40: - | M40: - | N40: =IFERROR(INDEX($F$1:$M$1,MATCH(MAX(F40:M40),F40:M40,0)),"Nincs ilyen!") -> 2014 | R40: =MAX(F40:M40)-MIN(F40:M40) -> 12.4
...

Sheet Jelmagyarázat
A1: Méret | B1: Jelentés | C1: Hallgatói létszám | E1: Kutatói intenzitás | F1: Jelentés
A2: XL | B2: Extra nagy | C2: >=30000 | E2: VH | F2: Nagyon magas
A3: L | B3: Nagy | C3: >=12000 | E3: HI | F3: Magas
A4: M | B4: Közepes | C4: >=5000 | E4: MD | F4: Közepes
A5: S | B5: Kicsi | C5: <5000 | E5: LO | F5: Alacsony
A7: Osztályzás | B7: Jelentés | C7: Életor
A8: 5 | B8: Történelmi | C8: Több, mint 100 éves
A9: 4 | B9: Érett | C9: 50 – 100 éves
A10: 3 | B10: Megalapozott | C10: 25 – 50 éves
A11: 2 | B11: Fiatal | C11: 10 - 25 éves
A12: 1 | B12: Új | C12: 10 évnél fiatalabb

Sheet Megoldások
A1: Egyetem neve | B1: Ecole des Ponts ParisTech | C1: =CONCATENATE(IF(COUNTIFS('Francia egyetemek QS rangsora'!A2:A50,B1)=0,"Nincs adat!",IF(VLOOKUP(B1,'Francia egyetemek QS rangsora'!A2:L50,12,FALSE)="-","Nincs adat!",COUNTIFS('Francia egyetemek QS rangsora'!L2:L50,">"&VLOOKUP(B1,'Francia egyetemek QS rangsora'!A2:L50,12,FALSE))))," db"," és ",AVERAGEIF('Francia egyetemek QS rangsora'!L2:L50,">"&VLOOKUP(B1,'Francia egyetemek QS rangsora'!A2:L50,12,FALSE))) -> 7 db és 55,4857142857143
A3: =IF('Francia egyetemek QS rangsora'!R1=0,"Nincs ilyen",INDEX('Francia egyetemek QS rangsora'!A2:A50,MATCH('Francia egyetemek QS rangsora'!R1,'Francia egyetemek QS rangsora'!R2:R50,0))) -> Université Paris Descartes
A5: =IF(1<COUNTIFS('Francia egyetemek QS rangsora'!L2:L50,_xlfn.MAXIFS('Francia egyetemek QS rangsora'!$L$2:$L$50,'Francia egyetemek QS rangsora'!$B$2:$B$50,"S")),"Több ilyen van!",INDEX('Francia egyetemek QS rangsora'!A2:A50,MATCH(_xlfn.MAXIFS('Francia egyetemek QS rangsora'!$L$2:$L$50,'Francia egyetemek QS rangsora'!$B$2:$B$50,"S"),'Francia egyetemek QS rangsora'!L2:L50,0))) -> Ecole Polytechnique
A7: =DCOUNTA('Francia egyetemek QS rangsora'!A1:N50,'Francia egyetemek QS rangsora'!A1,D8:G14) -> 2 | B7: =DAVERAGE('Francia egyetemek QS rangsora'!A1:N50,"2020",D8:G14) -> 36.05
D8: Város | E8: Kutatás | F8: Életkor | G8: Előző
D9: =NOT(ISERR(SEARCH("Párizs",'Francia egyetemek QS rangsora'!A2))) -> FALSE | E9: <>LO | F9: 5 | G9: =COUNTIFS('Francia egyetemek QS rangsora'!K2:M2,"-")=0 -> TRUE
D10: =NOT(ISERR(SEARCH("Párizs",'Francia egyetemek QS rangsora'!A2))) -> FALSE | E10: <>LO | F10: 4 | G10: =COUNTIFS('Francia egyetemek QS rangsora'!K2:M2,"-")=0 -> TRUE
D11: =NOT(ISERR(SEARCH("Lyon",'Francia egyetemek QS rangsora'!A2))) -> FALSE | E11: <>LO | F11: 5 | G11: =COUNTIFS('Francia egyetemek QS rangsora'!K2:M2,"-")=0 -> TRUE
D12: =NOT(ISERR(SEARCH("Lyon",'Francia egyetemek QS rangsora'!A2))) -> FALSE | E12: <>LO | F12: 4 | G12: =COUNTIFS('Francia egyetemek QS rangsora'!K2:M2,"-")=0 -> TRUE
D13: =NOT(ISERR(SEARCH("Marseilles",'Francia egyetemek QS rangsora'!A2))) -> FALSE | E13: <>LO | F13: 5 | G13: =COUNTIFS('Francia egyetemek QS rangsora'!K2:M2,"-")=0 -> TRUE
D14: =NOT(ISERR(SEARCH("Marseilles",'Francia egyetemek QS rangsora'!A2))) -> FALSE | E14: <>LO | F14: 4 | G14: =COUNTIFS('Francia egyetemek QS rangsora'!K2:M2,"-")=0 -> TRUE

Sheet Költözés
B1: 5 | C1: 10 | D1: 15 | E1: 20 | F1: 25 | G1: 30 | H1: 35 | I1: 40 | J1: 45 | K1: 50 | L1: 55 | M1: 60 | N1: 65 | O1: 70 | P1: 75 | Q1: 80 | R1: 85 | S1: 90 | T1: 95 | U1: 100
A2: 5 | B2: =((ROUNDUP(B$1/10,0)*25)+(ROUNDUP($A2/10,0)*15)+200)*1.2 -> 288 | C2: =((ROUNDUP(C$1/10,0)*25)+(ROUNDUP($A2/10,0)*15)+200)*1.2 -> 288 | D2: =((ROUNDUP(D$1/10,0)*25)+(ROUNDUP($A2/10,0)*15)+200)*1.2 -> 318 | E2: =((ROUNDUP(E$1/10,0)*25)+(ROUNDUP($A2/10,0)*15)+200)*1.2 -> 318 | F2: =((ROUNDUP(F$1/10,0)*25)+(ROUNDUP($A2/10,0)*15)+200)*1.2 -> 348 | G2: =((ROUNDUP(G$1/10,0)*25)+(ROUNDUP($A2/10,0)*15)+200)*1.2 -> 348 | H2: =((ROUNDUP(H$1/10,0)*25)+(ROUNDUP($A2/10,0)*15)+200)*1.2 -> 378 | I2: =((ROUNDUP(I$1/10,0)*25)+(ROUNDUP($A2/10,0)*15)+200)*1.2 -> 378 | ... U2: =((ROUNDUP(U$1/10,0)*25)+(ROUNDUP($A2/10,0)*15)+200)*1.2 -> 558
A3: 10 | B3: =((ROUNDUP(B$1/10,0)*25)+(ROUNDUP($A3/10,0)*15)+200)*1.2 -> 288 | C3: =((ROUNDUP(C$1/10,0)*25)+(ROUNDUP($A3/10,0)*15)+200)*1.2 -> 288 | D3: =((ROUNDUP(D$1/10,0)*25)+(ROUNDUP($A3/10,0)*15)+200)*1.2 -> 318 | E3: =((ROUNDUP(E$1/10,0)*25)+(ROUNDUP($A3/10,0)*15)+200)*1.2 -> 318 | F3: =((ROUNDUP(F$1/10,0)*25)+(ROUNDUP($A3/10,0)*15)+200)*1.2 -> 348 | G3: =((ROUNDUP(G$1/10,0)*25)+(ROUNDUP($A3/10,0)*15)+200)*1.2 -> 348 | H3: =((ROUNDUP(H$1/10,0)*25)+(ROUNDUP($A3/10,0)*15)+200)*1.2 -> 378 | I3: =((ROUNDUP(I$1/10,0)*25)+(ROUNDUP($A3/10,0)*15)+200)*1.2 -> 378 | ... U3: =((ROUNDUP(U$1/10,0)*25)+(ROUNDUP($A3/10,0)*15)+200)*1.2 -> 558
A4: 15 | B4: =((ROUNDUP(B$1/10,0)*25)+(ROUNDUP($A4/10,0)*15)+200)*1.2 -> 306 | C4: =((ROUNDUP(C$1/10,0)*25)+(ROUNDUP($A4/10,0)*15)+200)*1.2 -> 306 | D4: =((ROUNDUP(D$1/10,0)*25)+(ROUNDUP($A4/10,0)*15)+200)*1.2 -> 336 | E4: =((ROUNDUP(E$1/10,0)*25)+(ROUNDUP($A4/10,0)*15)+200)*1.2 -> 336 | F4: =((ROUNDUP(F$1/10,0)*25)+(ROUNDUP($A4/10,0)*15)+200)*1.2 -> 366 | G4: =((ROUNDUP(G$1/10,0)*25)+(ROUNDUP($A4/10,0)*15)+200)*1.2 -> 366 | H4: =((ROUNDUP(H$1/10,0)*25)+(ROUNDUP($A4/10,0)*15)+200)*1.2 -> 396 | I4: =((ROUNDUP(I$1/10,0)*25)+(ROUNDUP($A4/10,0)*15)+200)*1.2 -> 396 | ... U4: =((ROUNDUP(U$1/10,0)*25)+(ROUNDUP($A4/10,0)*15)+200)*1.2 -> 576
A5: 20 | B5: =((ROUNDUP(B$1/10,0)*25)+(ROUNDUP($A5/10,0)*15)+200)*1.2 -> 306 | C5: =((ROUNDUP(C$1/10,0)*25)+(ROUNDUP($A5/10,0)*15)+200)*1.2 -> 306 | D5: =((ROUNDUP(D$1/10,0)*25)+(ROUNDUP($A5/10,0)*15)+200)*1.2 -> 336 | E5: =((ROUNDUP(E$1/10,0)*25)+(ROUNDUP($A5/10,0)*15)+200)*1.2 -> 336 | F5: =((ROUNDUP(F$1/10,0)*25)+(ROUNDUP($A5/10,0)*15)+200)*1.2 -> 366 | G5: =((ROUNDUP(G$1/10,0)*25)+(ROUNDUP($A5/10,0)*15)+200)*1.2 -> 366 | H5: =((ROUNDUP(H$1/10,0)*25)+(ROUNDUP($A5/10,0)*15)+200)*1.2 -> 396 | I5: =((ROUNDUP(I$1/10,0)*25)+(ROUNDUP($A5/10,0)*15)+200)*1.2 -> 396 | ... U5: =((ROUNDUP(U$1/10,0)*25)+(ROUNDUP($A5/10,0)*15)+200)*1.2 -> 576
A6: 25 | B6: =((ROUNDUP(B$1/10,0)*25)+(ROUNDUP($A6/10,0)*15)+200)*1.2 -> 324 | C6: =((ROUNDUP(C$1/10,0)*25)+(ROUNDUP($A6/10,0)*15)+200)*1.2 -> 324 | D6: =((ROUNDUP(D$1/10,0)*25)+(ROUNDUP($A6/10,0)*15)+200)*1.2 -> 354 | E6: =((ROUNDUP(E$1/10,0)*25)+(ROUNDUP($A6/10,0)*15)+200)*1.2 -> 354 | F6: =((ROUNDUP(F$1/10,0)*25)+(ROUNDUP($A6/10,0)*15)+200)*1.2 -> 384 | G6: =((ROUNDUP(G$1/10,0)*25)+(ROUNDUP($A6/10,0)*15)+200)*1.2 -> 384 | H6: =((ROUNDUP(H$1/10,0)*25)+(ROUNDUP($A6/10,0)*15)+200)*1.2 -> 414 | I6: =((ROUNDUP(I$1/10,0)*25)+(ROUNDUP($A6/10,0)*15)+200)*1.2 -> 414 | ... U6: =((ROUNDUP(U$1/10,0)*25)+(ROUNDUP($A6/10,0)*15)+200)*1.2 -> 594
A7: 30 | B7: =((ROUNDUP(B$1/10,0)*25)+(ROUNDUP($A7/10,0)*15)+200)*1.2 -> 324 | C7: =((ROUNDUP(C$1/10,0)*25)+(ROUNDUP($A7/10,0)*15)+200)*1.2 -> 324 | D7: =((ROUNDUP(D$1/10,0)*25)+(ROUNDUP($A7/10,0)*15)+200)*1.2 -> 354 | E7: =((ROUNDUP(E$1/10,0)*25)+(ROUNDUP($A7/10,0)*15)+200)*1.2 -> 354 | F7: =((ROUNDUP(F$1/10,0)*25)+(ROUNDUP($A7/10,0)*15)+200)*1.2 -> 384 | G7: =((ROUNDUP(G$1/10,0)*25)+(ROUNDUP($A7/10,0)*15)+200)*1.2 -> 384 | H7: =((ROUNDUP(H$1/10,0)*25)+(ROUNDUP($A7/10,0)*15)+200)*1.2 -> 414 | I7: =((ROUNDUP(I$1/10,0)*25)+(ROUNDUP($A7/10,0)*15)+200)*1.2 -> 414 | ... U7: =((ROUNDUP(U$1/10,0)*25)+(ROUNDUP($A7/10,0)*15)+200)*1.2 -> 594
A8: 35 | B8: =((ROUNDUP(B$1/10,0)*25)+(ROUNDUP($A8/10,0)*15)+200)*1.2 -> 342 | C8: =((ROUNDUP(C$1/10,0)*25)+(ROUNDUP($A8/10,0)*15)+200)*1.2 -> 342 | D8: =((ROUNDUP(D$1/10,0)*25)+(ROUNDUP($A8/10,0)*15)+200)*1.2 -> 372 | E8: =((ROUNDUP(E$1/10,0)*25)+(ROUNDUP($A8/10,0)*15)+200)*1.2 -> 372 | F8: =((ROUNDUP(F$1/10,0)*25)+(ROUNDUP($A8/10,0)*15)+200)*1.2 -> 402 | G8: =((ROUNDUP(G$1/10,0)*25)+(ROUNDUP($A8/10,0)*15)+200)*1.2 -> 402 | H8: =((ROUNDUP(H$1/10,0)*25)+(ROUNDUP($A8/10,0)*15)+200)*1.2 -> 432 | I8: =((ROUNDUP(I$1/10,0)*25)+(ROUNDUP($A8/10,0)*15)+200)*1.2 -> 432 | ... U8: =((ROUNDUP(U$1/10,0)*25)+(ROUNDUP($A8/10,0)*15)+200)*1.2 -> 612
A9: 40 | B9: =((ROUNDUP(B$1/10,0)*25)+(ROUNDUP($A9/10,0)*15)+200)*1.2 -> 342 | C9: =((ROUNDUP(C$1/10,0)*25)+(ROUNDUP($A9/10,0)*15)+200)*1.2 -> 342 | D9: =((ROUNDUP(D$1/10,0)*25)+(ROUNDUP($A9/10,0)*15)+200)*1.2 -> 372 | E9: =((ROUNDUP(E$1/10,0)*25)+(ROUNDUP($A9/10,0)*15)+200)*1.2 -> 372 | F9: =((ROUNDUP(F$1/10,0)*25)+(ROUNDUP($A9/10,0)*15)+200)*1.2 -> 402 | G9: =((ROUNDUP(G$1/10,0)*25)+(ROUNDUP($A9/10,0)*15)+200)*1.2 -> 402 | H9: =((ROUNDUP(H$1/10,0)*25)+(ROUNDUP($A9/10,0)*15)+200)*1.2 -> 432 | I9: =((ROUNDUP(I$1/10,0)*25)+(ROUNDUP($A9/10,0)*15)+200)*1.2 -> 432 | ... U9: =((ROUNDUP(U$1/10,0)*25)+(ROUNDUP($A9/10,0)*15)+200)*1.2 -> 612
A10: 45 | B10: =((ROUNDUP(B$1/10,0)*25)+(ROUNDUP($A10/10,0)*15)+200)*1.2 -> 360 | C10: =((ROUNDUP(C$1/10,0)*25)+(ROUNDUP($A10/10,0)*15)+200)*1.2 -> 360 | D10: =((ROUNDUP(D$1/10,0)*25)+(ROUNDUP($A10/10,0)*15)+200)*1.2 -> 390 | E10: =((ROUNDUP(E$1/10,0)*25)+(ROUNDUP($A10/10,0)*15)+200)*1.2 -> 390 | F10: =((ROUNDUP(F$1/10,0)*25)+(ROUNDUP($A10/10,0)*15)+200)*1.2 -> 420 | G10: =((ROUNDUP(G$1/10,0)*25)+(ROUNDUP($A10/10,0)*15)+200)*1.2 -> 420 | H10: =((ROUNDUP(H$1/10,0)*25)+(ROUNDUP($A10/10,0)*15)+200)*1.2 -> 450 | I10: =((ROUNDUP(I$1/10,0)*25)+(ROUNDUP($A10/10,0)*15)+200)*1.2 -> 450 | ... U10: =((ROUNDUP(U$1/10,0)*25)+(ROUNDUP($A10/10,0)*15)+200)*1.2 -> 630
A11: 50 | B11: =((ROUNDUP(B$1/10,0)*25)+(ROUNDUP($A11/10,0)*15)+200)*1.2 -> 360 | C11: =((ROUNDUP(C$1/10,0)*25)+(ROUNDUP($A11/10,0)*15)+200)*1.2 -> 360 | D11: =((ROUNDUP(D$1/10,0)*25)+(ROUNDUP($A11/10,0)*15)+200)*1.2 -> 390 | E11: =((ROUNDUP(E$1/10,0)*25)+(ROUNDUP($A11/10,0)*15)+200)*1.2 -> 390 | F11: =((ROUNDUP(F$1/10,0)*25)+(ROUNDUP($A11/10,0)*15)+200)*1.2 -> 420 | G11: =((ROUNDUP(G$1/10,0)*25)+(ROUNDUP($A11/10,0)*15)+200)*1.2 -> 420 | H11: =((ROUNDUP(H$1/10,0)*25)+(ROUNDUP($A11/10,0)*15)+200)*1.2 -> 450 | I11: =((ROUNDUP(I$1/10,0)*25)+(ROUNDUP($A11/10,0)*15)+200)*1.2 -> 450 | ... U11: =((ROUNDUP(U$1/10,0)*25)+(ROUNDUP($A11/10,0)*15)+200)*1.2 -> 630
A12: 55 | B12: =((ROUNDUP(B$1/10,0)*25)+(ROUNDUP($A12/10,0)*15)+200)*1.2 -> 378 | C12: =((ROUNDUP(C$1/10,0)*25)+(ROUNDUP($A12/10,0)*15)+200)*1.2 -> 378 | D12: =((ROUNDUP(D$1/10,0)*25)+(ROUNDUP($A12/10,0)*15)+200)*1.2 -> 408 | E12: =((ROUNDUP(E$1/10,0)*25)+(ROUNDUP($A12/10,0)*15)+200)*1.2 -> 408 | F12: =((ROUNDUP(F$1/10,0)*25)+(ROUNDUP($A12/10,0)*15)+200)*1.2 -> 438 | G12: =((ROUNDUP(G$1/10,0)*25)+(ROUNDUP($A12/10,0)*15)+200)*1.2 -> 438 | H12: =((ROUNDUP(H$1/10,0)*25)+(ROUNDUP($A12/10,0)*15)+200)*1.2 -> 468 | I12: =((ROUNDUP(I$1/10,0)*25)+(ROUNDUP($A12/10,0)*15)+200)*1.2 -> 468 | ... U12: =((ROUNDUP(U$1/10,0)*25)+(ROUNDUP($A12/10,0)*15)+200)*1.2 -> 648
A13: 60 | B13: =((ROUNDUP(B$1/10,0)*25)+(ROUNDUP($A13/10,0)*15)+200)*1.2 -> 378 | C13: =((ROUNDUP(C$1/10,0)*25)+(ROUNDUP($A13/10,0)*15)+200)*1.2 -> 378 | D13: =((ROUNDUP(D$1/10,0)*25)+(ROUNDUP($A13/10,0)*15)+200)*1.2 -> 408 | E13: =((ROUNDUP(E$1/10,0)*25)+(ROUNDUP($A13/10,0)*15)+200)*1.2 -> 408 | F13: =((ROUNDUP(F$1/10,0)*25)+(ROUNDUP($A13/10,0)*15)+200)*1.2 -> 438 | G13: =((ROUNDUP(G$1/10,0)*25)+(ROUNDUP($A13/10,0)*15)+200)*1.2 -> 438 | H13: =((ROUNDUP(H$1/10,0)*25)+(ROUNDUP($A13/10,0)*15)+200)*1.2 -> 468 | I13: =((ROUNDUP(I$1/10,0)*25)+(ROUNDUP($A13/10,0)*15)+200)*1.2 -> 468 | ... U13: =((ROUNDUP(U$1/10,0)*25)+(ROUNDUP($A13/10,0)*15)+200)*1.2 -> 648
... A21: 100 | B21: =((ROUNDUP(B$1/10,0)*25)+(ROUNDUP($A21/10,0)*15)+200)*1.2 -> 450 | C21: =((ROUNDUP(C$1/10,0)*25)+(ROUNDUP($A21/10,0)*15)+200)*1.2 -> 450 | D21: =((ROUNDUP(D$1/10,0)*25)+(ROUNDUP($A21/10,0)*15)+200)*1.2 -> 480 | E21: =((ROUNDUP(E$1/10,0)*25)+(ROUNDUP($A21/10,0)*15)+200)*1.2 -> 480 | F21: =((ROUNDUP(F$1/10,0)*25)+(ROUNDUP($A21/10,0)*15)+200)*1.2 -> 510 | G21: =((ROUNDUP(G$1/10,0)*25)+(ROUNDUP($A21/10,0)*15)+200)*1.2 -> 510 | H21: =((ROUNDUP(H$1/10,0)*25)+(ROUNDUP($A21/10,0)*15)+200)*1.2 -> 540 | I21: =((ROUNDUP(I$1/10,0)*25)+(ROUNDUP($A21/10,0)*15)+200)*1.2 -> 540 | ... U21: =((ROUNDUP(U$1/10,0)*25)+(ROUNDUP($A21/10,0)*15)+200)*1.2 -> 720
